<robot name = "pan_tilt">

<link name = "base_link">
	<visual>
		<geometry>
			<box size = "0.032 0.05 0.04" />
		</geometry>
		<material name = "red">
			<color rgba = "1 0 0 1"/>
		</material>
	</visual>

</link>

<joint name = "PAN_JOINT" type = "revolute">
	<parent link = "base_link"/>
	<child link = "pan_link" />
	<axis xyz = "0 0 1"/>
	<origin xyz = "0 0.02 0.02"/>
	 <limit effort="100.0" lower="-0.45" upper="0.45" velocity="3"/>
</joint>

<link name = "pan_link">
    <visual>
    <geometry>
        <box size="0.04 0.032 0.05"/>
      </geometry>
	<origin xyz = "0.0 0.0 0.025" rpy = "0 0 1.57075"/>
		<material name = "grey">
			<color rgba = "0.411765 0.411765 0.411765 0.8"/>
		</material>
    </visual>
</link>


<joint name = "TILT_JOINT" type = "revolute">
	<parent link = "pan_link"/>
	<child link = "tilt_link" />
	<axis xyz = "0 0 1" />	
	<origin xyz = "0.0 0.015 0.04" rpy = "0 1.57075 0"/>
	 <limit effort="100.0" lower="-0.21" upper="2.09075" velocity="3"/>
</joint>


<link name = "tilt_link">
    <visual>
    <geometry>
        <box size="0.05 0.04 0.015"/>
      </geometry>
		<material name = "white">
			<color rgba = "1 1 1 1"/>
		</material>
	<origin xyz = "0.0 0.01 0" rpy = "1.57075 0 0"/>
    </visual>
</link>

<joint name = "camera" type = "fixed">
	<parent link = "tilt_link"/>
	<child link = "eye" />
	<axis xyz = "0 0 1"/>
	<origin xyz = "0.0 0.04 0.0" />
</joint> 


<link name = "eye">
	<visual>
		<geometry>
			<box size = " 0.05 0.04 0.05 " />
		</geometry> 
	
		<material name = "blue">
			<color rgba = " 0 0 1 1"/>
		</material>
			<origin xyz = "0.0 0.0 0.0" />
	</visual>
</link> 



<link name = "fixed_camera">
<visual>
		<geometry>
			<box size = " 0.04 0.03 0.01 " />
		</geometry> 
	
		<material name = "green">
			<color rgba = " 0 1 0 1"/>
		</material>
			<origin xyz = "0.0 0.0 0.0" rpy="0 0 0" />
	</visual>
</link> 


<joint name = "fixed_camera_joint" type = "fixed">
	<parent link = "base_link"/>
	<child link = "fixed_camera" />
	<axis xyz = "0 0 0"/>
	<origin xyz = "0.0 0.0 0.165" rpy="1.57 1.57 0" />
</joint> 

</robot>
